<sdf version='1.6'>
  <model name='iris'>
    <link name='base_link'>
      <pose frame=''>0 0 0 0 -0 0</pose>
      <inertial>
        <pose frame=''>2e-05 0 -3.6e-05 0 -0 0</pose>
        <mass>1.5012</mass>
        <inertia>
          <ixx>0.0354397</ixx>
          <ixy>0</ixy>
          <ixz>2.36356e-06</ixz>
          <iyy>0.0460307</iyy>
          <iyz>0</iyz>
          <izz>0.0983952</izz>
        </inertia>
      </inertial>
      <collision name='base_link_inertia_collision'>
        <pose frame=''>0 0 0 0 -0 0</pose>
        <geometry>
          <box>
            <size>0.47 0.47 0.11</size>
          </box>
        </geometry>
        <surface>
          <contact>
            <ode>
              <min_depth>0.001</min_depth>
              <max_vel>0</max_vel>
            </ode>
          </contact>
          <friction>
            <ode/>
          </friction>
        </surface>
      </collision>
      <collision name='base_link_fixed_joint_lump__downward_cam_link_collision_1'>
        <pose frame=''>0 0 -0.045 3.14159 1.57079 3.14159</pose>
        <geometry>
          <box>
            <size>0.01 0.01 0.01</size>
          </box>
        </geometry>
        <surface>
          <contact>
            <ode/>
          </contact>
          <friction>
            <ode/>
          </friction>
        </surface>
      </collision>
      <collision name='base_link_fixed_joint_lump__front_cam_link_collision_2'>
        <pose frame=''>0.15 0 -0.048 0 0.093 0</pose>
        <geometry>
          <box>
            <size>0.007 0.13 0.02</size>
          </box>
        </geometry>
        <surface>
          <contact>
            <ode/>
          </contact>
          <friction>
            <ode/>
          </friction>
        </surface>
      </collision>
      <visual name='base_link_inertia_visual'>
        <pose frame=''>0 0 0 0 -0 0</pose>
        <geometry>
          <mesh>
            <scale>1 1 1</scale>
            <uri>model://rotors_description/meshes/iris.stl</uri>
          </mesh>
        </geometry>
        <material>
          <script>
            <name>Gazebo/DarkGrey</name>
            <uri>file://media/materials/scripts/gazebo.material</uri>
          </script>
        </material>
      </visual>
      <visual name='base_link_fixed_joint_lump__downward_cam_link_visual_1'>
        <pose frame=''>0 0 -0.045 3.14159 1.57079 3.14159</pose>
        <geometry>
          <box>
            <size>0.01 0.01 0.01</size>
          </box>
        </geometry>
        <material>
          <script>
            <uri>__default__</uri>
            <name>__default__</name>
          </script>
        </material>
      </visual>
      <visual name='base_link_fixed_joint_lump__front_cam_link_visual_2'>
        <pose frame=''>0.15 0 -0.048 0 0.093 0</pose>
        <geometry>
          <box>
            <size>0.007 0.13 0.02</size>
          </box>
        </geometry>
        <material>
          <script>
            <name>Gazebo/Grey</name>
            <uri>file://media/materials/scripts/gazebo.material</uri>
          </script>
        </material>
      </visual>
      <velocity_decay/>
      <velocity_decay/>
      <sensor name='downward_cam_camera_sensor' type='camera'>
        <update_rate>77</update_rate>
        <camera name='__default__'>
          <horizontal_fov>0.924771</horizontal_fov>
          <image>
            <format>R8G8B8</format>
            <width>1228</width>
            <height>1027</height>
          </image>
          <clip>
            <near>0.01</near>
            <far>100</far>
          </clip>
        </camera>
        <plugin name='downward_cam_camera_controller' filename='libgazebo_ros_camera.so'>
          <cameraName>downward_cam</cameraName>
          <alwaysOn>true</alwaysOn>
          <updateRate>77</updateRate>
          <imageTopicName>camera/image</imageTopicName>
          <cameraInfoTopicName>camera/camera_info</cameraInfoTopicName>
          <frameName>downward_cam_optical_frame</frameName>
        </plugin>
        <pose frame=''>0 0 -0.045 3.14159 1.57079 3.14159</pose>
      </sensor>
      <velocity_decay/>
      <gravity>1</gravity>
      <velocity_decay/>
      <sensor name='front_cam' type='depth'>
        <update_rate>20</update_rate>
        <camera name='__default__'>
          <horizontal_fov>1.09607</horizontal_fov>
          <image>
            <format>R8G8B8</format>
            <width>640</width>
            <height>480</height>
          </image>
          <clip>
            <near>0.5</near>
            <far>9</far>
          </clip>
        </camera>
        <plugin name='front_cam_camera_controller' filename='libgazebo_ros_openni_kinect.so'>
          <imageTopicName>front_cam/rgb/image_raw</imageTopicName>
          <cameraInfoTopicName>front_cam/rgb/camera_info</cameraInfoTopicName>
          <depthImageTopicName>front_cam/depth/image_raw</depthImageTopicName>
          <depthImageCameraInfoTopicName>front_cam/depth/camera_info</depthImageCameraInfoTopicName>
          <pointCloudTopicName>front_cam/depth/points</pointCloudTopicName>
          <frameName>front_cam_depth_optical_frame</frameName>
        </plugin>
        <pose frame=''>0.15 0.049 -0.048 0 0.093 0</pose>
      </sensor>
    </link>
    <link name='/ground_truth/odometry_sensorgt_link'>
      <pose frame=''>0 0 0 0 -0 0</pose>
      <inertial>
        <pose frame=''>0 0 0 0 -0 0</pose>
        <mass>1e-05</mass>
        <inertia>
          <ixx>1e-05</ixx>
          <ixy>0</ixy>
          <ixz>0</ixz>
          <iyy>1e-05</iyy>
          <iyz>0</iyz>
          <izz>1e-05</izz>
        </inertia>
      </inertial>
    </link>
    <joint name='/ground_truth/odometry_sensorgt_joint' type='revolute'>
      <child>/ground_truth/odometry_sensorgt_link</child>
      <parent>base_link</parent>
      <axis>
        <xyz>1 0 0</xyz>
        <limit>
          <lower>0</lower>
          <upper>0</upper>
          <effort>0</effort>
          <velocity>0</velocity>
        </limit>
        <dynamics>
          <spring_reference>0</spring_reference>
          <spring_stiffness>0</spring_stiffness>
        </dynamics>
        <use_parent_model_frame>1</use_parent_model_frame>
      </axis>
    </joint>
    <link name='/imu_link'>
      <pose frame=''>0 0 0 0 -0 0</pose>
      <inertial>
        <pose frame=''>0 0 0 0 -0 0</pose>
        <mass>0.015</mass>
        <inertia>
          <ixx>1e-05</ixx>
          <ixy>0</ixy>
          <ixz>0</ixz>
          <iyy>1e-05</iyy>
          <iyz>0</iyz>
          <izz>1e-05</izz>
        </inertia>
      </inertial>
    </link>
    <joint name='/imu_joint' type='revolute'>
      <child>/imu_link</child>
      <parent>base_link</parent>
      <axis>
        <xyz>1 0 0</xyz>
        <limit>
          <lower>0</lower>
          <upper>0</upper>
          <effort>0</effort>
          <velocity>0</velocity>
        </limit>
        <dynamics>
          <spring_reference>0</spring_reference>
          <spring_stiffness>0</spring_stiffness>
        </dynamics>
        <use_parent_model_frame>1</use_parent_model_frame>
      </axis>
    </joint>
    <link name='/imugt_link'>
      <pose frame=''>0 0 0 0 -0 0</pose>
      <inertial>
        <pose frame=''>0 0 0 0 -0 0</pose>
        <mass>1e-05</mass>
        <inertia>
          <ixx>1e-05</ixx>
          <ixy>0</ixy>
          <ixz>0</ixz>
          <iyy>1e-05</iyy>
          <iyz>0</iyz>
          <izz>1e-05</izz>
        </inertia>
      </inertial>
    </link>
    <joint name='/imugt_joint' type='revolute'>
      <child>/imugt_link</child>
      <parent>base_link</parent>
      <axis>
        <xyz>1 0 0</xyz>
        <limit>
          <lower>0</lower>
          <upper>0</upper>
          <effort>0</effort>
          <velocity>0</velocity>
        </limit>
        <dynamics>
          <spring_reference>0</spring_reference>
          <spring_stiffness>0</spring_stiffness>
        </dynamics>
        <use_parent_model_frame>1</use_parent_model_frame>
      </axis>
    </joint>
    <link name='rotor_0'>
      <pose frame=''>0.13 -0.22 0.023 0 -0 0</pose>
      <inertial>
        <pose frame=''>0 0 0 0 -0 0</pose>
        <mass>0.005</mass>
        <inertia>
          <ixx>9.75e-07</ixx>
          <ixy>0</ixy>
          <ixz>0</ixz>
          <iyy>0.000273104</iyy>
          <iyz>0</iyz>
          <izz>0.000274004</izz>
        </inertia>
      </inertial>
      <collision name='rotor_0_collision'>
        <pose frame=''>0 0 0 0 -0 0</pose>
        <geometry>
          <cylinder>
            <length>0.005</length>
            <radius>0.128</radius>
          </cylinder>
        </geometry>
        <surface>
          <contact>
            <ode/>
          </contact>
          <friction>
            <ode/>
          </friction>
        </surface>
      </collision>
      <visual name='rotor_0_visual'>
        <pose frame=''>0 0 0 0 -0 0</pose>
        <geometry>
          <mesh>
            <scale>1 1 1</scale>
            <uri>model://rotors_description/meshes/iris_prop_ccw.dae</uri>
          </mesh>
        </geometry>
        <material>
          <script>
            <name>Gazebo/Blue</name>
            <uri>file://media/materials/scripts/gazebo.material</uri>
          </script>
        </material>
      </visual>
      <gravity>1</gravity>
      <velocity_decay/>
    </link>
    <joint name='rotor_0_joint' type='revolute'>
      <child>rotor_0</child>
      <parent>base_link</parent>
      <axis>
        <xyz>0 0 1</xyz>
        <limit>
          <lower>-1e+16</lower>
          <upper>1e+16</upper>
        </limit>
        <dynamics>
          <spring_reference>0</spring_reference>
          <spring_stiffness>0</spring_stiffness>
        </dynamics>
        <use_parent_model_frame>1</use_parent_model_frame>
      </axis>
    </joint>
    <link name='rotor_1'>
      <pose frame=''>-0.13 0.2 0.023 0 -0 0</pose>
      <inertial>
        <pose frame=''>0 0 0 0 -0 0</pose>
        <mass>0.005</mass>
        <inertia>
          <ixx>9.75e-07</ixx>
          <ixy>0</ixy>
          <ixz>0</ixz>
          <iyy>0.000273104</iyy>
          <iyz>0</iyz>
          <izz>0.000274004</izz>
        </inertia>
      </inertial>
      <collision name='rotor_1_collision'>
        <pose frame=''>0 0 0 0 -0 0</pose>
        <geometry>
          <cylinder>
            <length>0.005</length>
            <radius>0.128</radius>
          </cylinder>
        </geometry>
        <surface>
          <contact>
            <ode/>
          </contact>
          <friction>
            <ode/>
          </friction>
        </surface>
      </collision>
      <visual name='rotor_1_visual'>
        <pose frame=''>0 0 0 0 -0 0</pose>
        <geometry>
          <mesh>
            <scale>1 1 1</scale>
            <uri>model://rotors_description/meshes/iris_prop_ccw.dae</uri>
          </mesh>
        </geometry>
        <material>
          <script>
            <name>Gazebo/DarkGrey</name>
            <uri>file://media/materials/scripts/gazebo.material</uri>
          </script>
        </material>
      </visual>
      <gravity>1</gravity>
      <velocity_decay/>
    </link>
    <joint name='rotor_1_joint' type='revolute'>
      <child>rotor_1</child>
      <parent>base_link</parent>
      <axis>
        <xyz>0 0 1</xyz>
        <limit>
          <lower>-1e+16</lower>
          <upper>1e+16</upper>
        </limit>
        <dynamics>
          <spring_reference>0</spring_reference>
          <spring_stiffness>0</spring_stiffness>
        </dynamics>
        <use_parent_model_frame>1</use_parent_model_frame>
      </axis>
    </joint>
    <link name='rotor_2'>
      <pose frame=''>0.13 0.22 0.023 0 -0 0</pose>
      <inertial>
        <pose frame=''>0 0 0 0 -0 0</pose>
        <mass>0.005</mass>
        <inertia>
          <ixx>9.75e-07</ixx>
          <ixy>0</ixy>
          <ixz>0</ixz>
          <iyy>0.000273104</iyy>
          <iyz>0</iyz>
          <izz>0.000274004</izz>
        </inertia>
      </inertial>
      <collision name='rotor_2_collision'>
        <pose frame=''>0 0 0 0 -0 0</pose>
        <geometry>
          <cylinder>
            <length>0.005</length>
            <radius>0.128</radius>
          </cylinder>
        </geometry>
        <surface>
          <contact>
            <ode/>
          </contact>
          <friction>
            <ode/>
          </friction>
        </surface>
      </collision>
      <visual name='rotor_2_visual'>
        <pose frame=''>0 0 0 0 -0 0</pose>
        <geometry>
          <mesh>
            <scale>1 1 1</scale>
            <uri>model://rotors_description/meshes/iris_prop_cw.dae</uri>
          </mesh>
        </geometry>
        <material>
          <script>
            <name>Gazebo/Blue</name>
            <uri>file://media/materials/scripts/gazebo.material</uri>
          </script>
        </material>
      </visual>
      <gravity>1</gravity>
      <velocity_decay/>
    </link>
    <joint name='rotor_2_joint' type='revolute'>
      <child>rotor_2</child>
      <parent>base_link</parent>
      <axis>
        <xyz>0 0 1</xyz>
        <limit>
          <lower>-1e+16</lower>
          <upper>1e+16</upper>
        </limit>
        <dynamics>
          <spring_reference>0</spring_reference>
          <spring_stiffness>0</spring_stiffness>
        </dynamics>
        <use_parent_model_frame>1</use_parent_model_frame>
      </axis>
    </joint>
    <link name='rotor_3'>
      <pose frame=''>-0.13 -0.2 0.023 0 -0 0</pose>
      <inertial>
        <pose frame=''>0 0 0 0 -0 0</pose>
        <mass>0.005</mass>
        <inertia>
          <ixx>9.75e-07</ixx>
          <ixy>0</ixy>
          <ixz>0</ixz>
          <iyy>0.000273104</iyy>
          <iyz>0</iyz>
          <izz>0.000274004</izz>
        </inertia>
      </inertial>
      <collision name='rotor_3_collision'>
        <pose frame=''>0 0 0 0 -0 0</pose>
        <geometry>
          <cylinder>
            <length>0.005</length>
            <radius>0.128</radius>
          </cylinder>
        </geometry>
        <surface>
          <contact>
            <ode/>
          </contact>
          <friction>
            <ode/>
          </friction>
        </surface>
      </collision>
      <visual name='rotor_3_visual'>
        <pose frame=''>0 0 0 0 -0 0</pose>
        <geometry>
          <mesh>
            <scale>1 1 1</scale>
            <uri>model://rotors_description/meshes/iris_prop_cw.dae</uri>
          </mesh>
        </geometry>
        <material>
          <script>
            <name>Gazebo/DarkGrey</name>
            <uri>file://media/materials/scripts/gazebo.material</uri>
          </script>
        </material>
      </visual>
      <gravity>1</gravity>
      <velocity_decay/>
    </link>
    <joint name='rotor_3_joint' type='revolute'>
      <child>rotor_3</child>
      <parent>base_link</parent>
      <axis>
        <xyz>0 0 1</xyz>
        <limit>
          <lower>-1e+16</lower>
          <upper>1e+16</upper>
        </limit>
        <dynamics>
          <spring_reference>0</spring_reference>
          <spring_stiffness>0</spring_stiffness>
        </dynamics>
        <use_parent_model_frame>1</use_parent_model_frame>
      </axis>
    </joint>
    <plugin name='rosbag' filename='librotors_gazebo_multirotor_base_plugin.so'>
      <robotNamespace/>
      <linkName>base_link</linkName>
      <rotorVelocitySlowdownSim>10</rotorVelocitySlowdownSim>
    </plugin>
    <plugin name='front_right_motor_model' filename='librotors_gazebo_motor_model.so'>
      <robotNamespace/>
      <jointName>rotor_0_joint</jointName>
      <linkName>rotor_0</linkName>
      <turningDirection>ccw</turningDirection>
      <timeConstantUp>0.0125</timeConstantUp>
      <timeConstantDown>0.025</timeConstantDown>
      <maxRotVelocity>1100</maxRotVelocity>
      <motorConstant>8.54858e-06</motorConstant>
      <momentConstant>0.06</momentConstant>
      <commandSubTopic>/gazebo/command/motor_speed</commandSubTopic>
      <motorNumber>0</motorNumber>
      <rotorDragCoefficient>0.000806428</rotorDragCoefficient>
      <rollingMomentCoefficient>1e-06</rollingMomentCoefficient>
      <motorSpeedPubTopic>/motor_speed/0</motorSpeedPubTopic>
      <rotorVelocitySlowdownSim>10</rotorVelocitySlowdownSim>
    </plugin>
    <plugin name='back_left_motor_model' filename='librotors_gazebo_motor_model.so'>
      <robotNamespace/>
      <jointName>rotor_1_joint</jointName>
      <linkName>rotor_1</linkName>
      <turningDirection>ccw</turningDirection>
      <timeConstantUp>0.0125</timeConstantUp>
      <timeConstantDown>0.025</timeConstantDown>
      <maxRotVelocity>1100</maxRotVelocity>
      <motorConstant>8.54858e-06</motorConstant>
      <momentConstant>0.06</momentConstant>
      <commandSubTopic>/gazebo/command/motor_speed</commandSubTopic>
      <motorNumber>1</motorNumber>
      <rotorDragCoefficient>0.000806428</rotorDragCoefficient>
      <rollingMomentCoefficient>1e-06</rollingMomentCoefficient>
      <motorSpeedPubTopic>/motor_speed/1</motorSpeedPubTopic>
      <rotorVelocitySlowdownSim>10</rotorVelocitySlowdownSim>
    </plugin>
    <plugin name='front_left_motor_model' filename='librotors_gazebo_motor_model.so'>
      <robotNamespace/>
      <jointName>rotor_2_joint</jointName>
      <linkName>rotor_2</linkName>
      <turningDirection>cw</turningDirection>
      <timeConstantUp>0.0125</timeConstantUp>
      <timeConstantDown>0.025</timeConstantDown>
      <maxRotVelocity>1100</maxRotVelocity>
      <motorConstant>8.54858e-06</motorConstant>
      <momentConstant>0.06</momentConstant>
      <commandSubTopic>/gazebo/command/motor_speed</commandSubTopic>
      <motorNumber>2</motorNumber>
      <rotorDragCoefficient>0.000806428</rotorDragCoefficient>
      <rollingMomentCoefficient>1e-06</rollingMomentCoefficient>
      <motorSpeedPubTopic>/motor_speed/2</motorSpeedPubTopic>
      <rotorVelocitySlowdownSim>10</rotorVelocitySlowdownSim>
    </plugin>
    <plugin name='back_right_motor_model' filename='librotors_gazebo_motor_model.so'>
      <robotNamespace/>
      <jointName>rotor_3_joint</jointName>
      <linkName>rotor_3</linkName>
      <turningDirection>cw</turningDirection>
      <timeConstantUp>0.0125</timeConstantUp>
      <timeConstantDown>0.025</timeConstantDown>
      <maxRotVelocity>1100</maxRotVelocity>
      <motorConstant>8.54858e-06</motorConstant>
      <momentConstant>0.06</momentConstant>
      <commandSubTopic>/gazebo/command/motor_speed</commandSubTopic>
      <motorNumber>3</motorNumber>
      <rotorDragCoefficient>0.000806428</rotorDragCoefficient>
      <rollingMomentCoefficient>1e-06</rollingMomentCoefficient>
      <motorSpeedPubTopic>/motor_speed/3</motorSpeedPubTopic>
      <rotorVelocitySlowdownSim>10</rotorVelocitySlowdownSim>
    </plugin>
    <plugin name='mavlink_interface' filename='librotors_gazebo_mavlink_interface.so'>
      <robotNamespace/>
      <imuSubTopic>/imu</imuSubTopic>
      <mavlink_addr>INADDR_ANY</mavlink_addr>
      <mavlink_udp_port>14560</mavlink_udp_port>
      <motorSpeedCommandPubTopic>/gazebo/command/motor_speed</motorSpeedCommandPubTopic>
      <control_channels>
        <channel name='rotor1'>
          <input_index>0</input_index>
          <input_offset>0</input_offset>
          <input_scaling>1000</input_scaling>
          <zero_position_disarmed>0</zero_position_disarmed>
          <zero_position_armed>100</zero_position_armed>
          <joint_control_type>velocity</joint_control_type>
        </channel>
        <channel name='rotor2'>
          <input_index>1</input_index>
          <input_offset>0</input_offset>
          <input_scaling>1000</input_scaling>
          <zero_position_disarmed>0</zero_position_disarmed>
          <zero_position_armed>100</zero_position_armed>
          <joint_control_type>velocity</joint_control_type>
        </channel>
        <channel name='rotor3'>
          <input_index>2</input_index>
          <input_offset>0</input_offset>
          <input_scaling>1000</input_scaling>
          <zero_position_disarmed>0</zero_position_disarmed>
          <zero_position_armed>100</zero_position_armed>
          <joint_control_type>velocity</joint_control_type>
        </channel>
        <channel name='rotor4'>
          <input_index>3</input_index>
          <input_offset>0</input_offset>
          <input_scaling>1000</input_scaling>
          <zero_position_disarmed>0</zero_position_disarmed>
          <zero_position_armed>100</zero_position_armed>
          <joint_control_type>velocity</joint_control_type>
        </channel>
        <channel name='rotor5'>
          <input_index>4</input_index>
          <input_offset>1</input_offset>
          <input_scaling>324.6</input_scaling>
          <zero_position_disarmed>0</zero_position_disarmed>
          <zero_position_armed>0</zero_position_armed>
          <joint_control_type>velocity</joint_control_type>
          <joint_control_pid>
            <p>0.1</p>
            <i>0</i>
            <d>0</d>
            <iMax>0.0</iMax>
            <iMin>0.0</iMin>
            <cmdMax>2</cmdMax>
            <cmdMin>-2</cmdMin>
          </joint_control_pid>
          <joint_name>zephyr_delta_wing::propeller_joint</joint_name>
        </channel>
        <channel name='rotor6'>
          <input_index>5</input_index>
          <input_offset>0</input_offset>
          <input_scaling>0.524</input_scaling>
          <zero_position_disarmed>0</zero_position_disarmed>
          <zero_position_armed>0</zero_position_armed>
          <joint_control_type>position</joint_control_type>
          <joint_name>zephyr_delta_wing::flap_left_joint</joint_name>
          <joint_control_pid>
            <p>10.0</p>
            <i>0</i>
            <d>0</d>
            <iMax>0</iMax>
            <iMin>0</iMin>
            <cmdMax>20</cmdMax>
            <cmdMin>-20</cmdMin>
          </joint_control_pid>
        </channel>
        <channel name='rotor7'>
          <input_index>6</input_index>
          <input_offset>0</input_offset>
          <input_scaling>0.524</input_scaling>
          <zero_position_disarmed>0</zero_position_disarmed>
          <zero_position_armed>0</zero_position_armed>
          <joint_control_type>position</joint_control_type>
          <joint_name>zephyr_delta_wing::flap_right_joint</joint_name>
          <joint_control_pid>
            <p>10.0</p>
            <i>0</i>
            <d>0</d>
            <iMax>0</iMax>
            <iMin>0</iMin>
            <cmdMax>20</cmdMax>
            <cmdMin>-20</cmdMin>
          </joint_control_pid>
        </channel>
        <channel name='rotor8'>
          <input_index>7</input_index>
          <input_offset>0</input_offset>
          <input_scaling>0.524</input_scaling>
          <zero_position_disarmed>0</zero_position_disarmed>
          <zero_position_armed>0</zero_position_armed>
          <joint_control_type>position</joint_control_type>
        </channel>
      </control_channels>
    </plugin>
    <plugin name='rotors_gazebo_imu_plugin' filename='librotors_gazebo_imu_plugin.so'>
      <robotNamespace/>
      <linkName>/imu_link</linkName>
      <imuTopic>/imu</imuTopic>
      <gyroscopeNoiseDensity>0.0003394</gyroscopeNoiseDensity>
      <gyroscopeRandomWalk>3.8785e-05</gyroscopeRandomWalk>
      <gyroscopeBiasCorrelationTime>1000.0</gyroscopeBiasCorrelationTime>
      <gyroscopeTurnOnBiasSigma>0.0087</gyroscopeTurnOnBiasSigma>
      <accelerometerNoiseDensity>0.004</accelerometerNoiseDensity>
      <accelerometerRandomWalk>0.006</accelerometerRandomWalk>
      <accelerometerBiasCorrelationTime>300.0</accelerometerBiasCorrelationTime>
      <accelerometerTurnOnBiasSigma>0.196</accelerometerTurnOnBiasSigma>
    </plugin>
    <plugin name='rotors_gazebo_imugt_plugin' filename='librotors_gazebo_imu_plugin.so'>
      <robotNamespace/>
      <linkName>/imugt_link</linkName>
      <imuTopic>ground_truth/imu</imuTopic>
      <gyroscopeNoiseDensity>0.0</gyroscopeNoiseDensity>
      <gyroscopeRandomWalk>0.0</gyroscopeRandomWalk>
      <gyroscopeBiasCorrelationTime>1000.0</gyroscopeBiasCorrelationTime>
      <gyroscopeTurnOnBiasSigma>0.0</gyroscopeTurnOnBiasSigma>
      <accelerometerNoiseDensity>0.0</accelerometerNoiseDensity>
      <accelerometerRandomWalk>0.0</accelerometerRandomWalk>
      <accelerometerBiasCorrelationTime>300.0</accelerometerBiasCorrelationTime>
      <accelerometerTurnOnBiasSigma>0.0</accelerometerTurnOnBiasSigma>
    </plugin>
    <plugin name='odometry_sensorgt' filename='librotors_gazebo_odometry_plugin.so'>
      <linkName>/ground_truth/odometry_sensorgt_link</linkName>
      <robotNamespace>/ground_truth</robotNamespace>
      <poseTopic>pose</poseTopic>
      <poseWithCovarianceTopic>pose_with_covariance</poseWithCovarianceTopic>
      <positionTopic>position</positionTopic>
      <transformTopic>transform</transformTopic>
      <odometryTopic>odometry</odometryTopic>
      <parentFrameId>world</parentFrameId>
      <measurementDivisor>1</measurementDivisor>
      <measurementDelay>0</measurementDelay>
      <unknownDelay>0.0</unknownDelay>
      <noiseNormalPosition>0 0 0</noiseNormalPosition>
      <noiseNormalQuaternion>0 0 0</noiseNormalQuaternion>
      <noiseNormalLinearVelocity>0 0 0</noiseNormalLinearVelocity>
      <noiseNormalAngularVelocity>0 0 0</noiseNormalAngularVelocity>
      <noiseUniformPosition>0 0 0</noiseUniformPosition>
      <noiseUniformQuaternion>0 0 0</noiseUniformQuaternion>
      <noiseUniformLinearVelocity>0 0 0</noiseUniformLinearVelocity>
      <noiseUniformAngularVelocity>0 0 0</noiseUniformAngularVelocity>
    </plugin>
    <static>0</static>
    <plugin name='gps_controller' filename='libhector_gazebo_ros_gps.so'>
      <updateRate>40</updateRate>
      <robotNamespace>/</robotNamespace>
      <bodyName>base_link</bodyName>
      <frameId>base_link</frameId>
      <topicName>navsat/fix</topicName>
      <velocityTopicName>navsat/vel</velocityTopicName>
      <referenceLatitude>49.9</referenceLatitude>
      <referenceLongitude>8.9</referenceLongitude>
      <referenceHeading>0</referenceHeading>
      <referenceAltitude>0</referenceAltitude>
      <drift>0.0001 0.0001 0.0001</drift>
    </plugin>





  <gazebo reference="thermal_frame">
      <sensor:camera name="thermal_camera_sensor">
        <imageSize>160 120</imageSize>
        <imageFormat>R8G8B8</imageFormat>
        <hfov>90</hfov>
        <nearClip>0.01</nearClip>
        <farClip>100</farClip>
        <updateRate>10</updateRate>
        <controller:gazebo_ros_thermal_camera name="thermal_camera_controller" plugin="libgazebo_ros_thermal_depth_camera.so">
          <alwaysOn>true</alwaysOn>
          <updateRate>10</updateRate>
          <imageTopicName>/thermal_camera/image_raw</imageTopicName>
          <cameraInfoTopicName>/thermal_camera/camera_info</cameraInfoTopicName>
          <frameName>thermal_optical_frame</frameName>
          <interface:camera name="thermal_camera_iface" />
        </controller:gazebo_ros_thermal_camera>
      </sensor:camera>
    </gazebo>




  </model>
</sdf>
