<sdf version='1.6'>
  <model name='pan_tilt'>
    <link name='base_link'>
      <pose frame=''>0 0 0 0 -0 0</pose>
      <inertial>
        <pose frame=''>0 0 0 0 -0 0</pose>
        <mass>1</mass>
        <inertia>
          <ixx>0.5</ixx>
          <ixy>0</ixy>
          <ixz>0</ixz>
          <iyy>0.5</iyy>
          <iyz>0</iyz>
          <izz>0.5</izz>
        </inertia>
      </inertial>
      <collision name='base_link_collision'>
        <pose frame=''>0 0 0 0 -0 0</pose>
        <geometry>
          <cylinder>
            <length>0.03</length>
            <radius>0.2</radius>
          </cylinder>
        </geometry>
      </collision>
      <visual name='base_link_visual'>
        <pose frame=''>0 0 0 0 -0 0</pose>
        <geometry>
          <cylinder>
            <length>0.01</length>
            <radius>0.2</radius>
          </cylinder>
        </geometry>
      </visual>
    </link>
    <link name='pan_link'>
      <pose frame=''>0 0 0.1 0 -0 0</pose>
      <inertial>
        <pose frame=''>0 0 0 0 -0 0</pose>
        <mass>1</mass>
        <inertia>
          <ixx>0.5</ixx>
          <ixy>0</ixy>
          <ixz>0</ixz>
          <iyy>0.5</iyy>
          <iyz>0</iyz>
          <izz>0.5</izz>
        </inertia>
      </inertial>
      <collision name='pan_link_collision'>
        <pose frame=''>0 0 0 0 -0 0</pose>
        <geometry>
          <cylinder>
            <length>0.4</length>
            <radius>0.06</radius>
          </cylinder>
        </geometry>
      </collision>
      <visual name='pan_link_visual'>
        <pose frame=''>0 0 0 0 -0 0</pose>
        <geometry>
          <cylinder>
            <length>0.4</length>
            <radius>0.04</radius>
          </cylinder>
        </geometry>
      </visual>
    </link>
    <joint name='pan_joint' type='revolute'>
      <child>pan_link</child>
      <parent>base_link</parent>
      <axis>
        <xyz>0 0 1</xyz>
        <limit>
          <lower>-3.14</lower>
          <upper>3.14</upper>
          <effort>300</effort>
          <velocity>0.1</velocity>
        </limit>
        <dynamics>
          <damping>50</damping>
          <friction>1</friction>
          <spring_reference>0</spring_reference>
          <spring_stiffness>0</spring_stiffness>
        </dynamics>
        <use_parent_model_frame>1</use_parent_model_frame>
      </axis>
    </joint>
    <link name='tilt_link'>
      <pose frame=''>0 0 0.5 0 -0 0</pose>
      <inertial>
        <pose frame=''>0 0 0 0 -0 0</pose>
        <mass>1</mass>
        <inertia>
          <ixx>0.5</ixx>
          <ixy>0</ixy>
          <ixz>0</ixz>
          <iyy>0.5</iyy>
          <iyz>0</iyz>
          <izz>0.5</izz>
        </inertia>
      </inertial>
      <collision name='tilt_link_collision'>
        <pose frame=''>0 0 0 0 1.57 0</pose>
        <geometry>
          <cylinder>
            <length>0.4</length>
            <radius>0.24</radius>
          </cylinder>
        </geometry>
      </collision>
      <visual name='tilt_link_visual'>
        <pose frame=''>0 0 0 0 1.57 0</pose>
        <geometry>
          <cylinder>
            <length>0.4</length>
            <radius>0.04</radius>
          </cylinder>
        </geometry>
      </visual>
    </link>
    <joint name='tilt_joint' type='revolute'>
      <child>tilt_link</child>
      <parent>pan_link</parent>
      <axis>
        <xyz>0 1 0</xyz>
        <limit>
          <lower>0</lower>
          <upper>0</upper>
          <effort>300</effort>
          <velocity>0.1</velocity>
        </limit>
        <dynamics>
          <damping>50</damping>
          <friction>1</friction>
          <spring_reference>0</spring_reference>
          <spring_stiffness>0</spring_stiffness>
        </dynamics>
        <use_parent_model_frame>1</use_parent_model_frame>
      </axis>
    </joint>
  </model>
</sdf>
